Failure # 1 (occurred at 2022-05-23_01-04-00)
Traceback (most recent call last):
  File "/home/jake/.local/lib/python3.8/site-packages/ray/tune/ray_trial_executor.py", line 901, in get_next_executor_event
    future_result = ray.get(ready_future)
  File "/home/jake/.local/lib/python3.8/site-packages/ray/_private/client_mode_hook.py", line 105, in wrapper
    return func(*args, **kwargs)
  File "/home/jake/.local/lib/python3.8/site-packages/ray/worker.py", line 1811, in get
    raise value
ray.exceptions.RayActorError: The actor died because of an error raised in its creation task, [36mray::PPOTrainer.__init__()[39m (pid=76111, ip=192.168.0.154, repr=PPOTrainer)
  File "/home/jake/.local/lib/python3.8/site-packages/ray/rllib/agents/trainer.py", line 1035, in _init
    raise NotImplementedError
NotImplementedError

During handling of the above exception, another exception occurred:

[36mray::PPOTrainer.__init__()[39m (pid=76111, ip=192.168.0.154, repr=PPOTrainer)
  File "/home/jake/.local/lib/python3.8/site-packages/ray/rllib/agents/trainer.py", line 830, in __init__
    super().__init__(
  File "/home/jake/.local/lib/python3.8/site-packages/ray/tune/trainable.py", line 149, in __init__
    self.setup(copy.deepcopy(self.config))
  File "/home/jake/.local/lib/python3.8/site-packages/ray/rllib/agents/trainer.py", line 911, in setup
    self.workers = WorkerSet(
  File "/home/jake/.local/lib/python3.8/site-packages/ray/rllib/evaluation/worker_set.py", line 134, in __init__
    remote_spaces = ray.get(
ray.exceptions.RayActorError: The actor died because of an error raised in its creation task, [36mray::RolloutWorker.__init__()[39m (pid=76167, ip=192.168.0.154, repr=<ray.rllib.evaluation.rollout_worker.RolloutWorker object at 0x7f2e81f3d730>)
  File "/home/jake/.local/lib/python3.8/site-packages/ray/rllib/evaluation/rollout_worker.py", line 507, in __init__
    check_env(self.env)
  File "/home/jake/.local/lib/python3.8/site-packages/ray/rllib/utils/pre_checks/env.py", line 65, in check_env
    check_gym_environments(env)
  File "/home/jake/.local/lib/python3.8/site-packages/ray/rllib/utils/pre_checks/env.py", line 160, in check_gym_environments
    next_obs, reward, done, info = env.step(sampled_action)
  File "<ipython-input-2-aade473ef6e8>", line 386, in step
  File "<__array_function__ internals>", line 180, in concatenate
ValueError: all the input array dimensions for the concatenation axis must match exactly, but along dimension 1, the array at index 0 has size 84 and the array at index 1 has size 16

